# 4.7.5 How to deal with more than one exception

# Two exceptions after one try
print()

try:
    value = int(input('Enter a natural number: '))
    print('The reciprocal of', value, 'is', 1/value)
except ValueError:
    print('I do not know what to do.')
except ZeroDivisionError:
    print('Division by zero is not allowed in our Universe.')
